<?xml version="1.0" ?>
<sdf version="1.12">
  <model name="neos">
    <link name="base_link">
      <inertial>
        <pose>0 0 -0.0008627450980392159 0 0 0</pose>
        <mass>10.199999999999999</mass>
        <inertia>
          <ixx>0.1005796078431373</ixx>
          <ixy>0</ixy>
          <ixz>0</ixz>
          <iyy>0.1050796078431373</iyy>
          <iyz>0</iyz>
          <izz>0.1047</izz>
        </inertia>
      </inertial>
      <collision name="base_link_collision">
        <pose>0 0 0 0 0 0</pose>
        <geometry>
          <cylinder>
            <length>0.10000000000000001</length>
            <radius>0.20000000000000001</radius>
          </cylinder>
        </geometry>
      </collision>
      <collision name="base_link_fixed_joint_lump__front_caster_collision_1">
        <pose>0.14999999999999999 0 -0.043999999999999997 0 0 0</pose>
        <geometry>
          <sphere>
            <radius>0.029999999999999999</radius>
          </sphere>
        </geometry>
      </collision>
      <collision name="base_link_fixed_joint_lump__rear_caster_collision_2">
        <pose>-0.14999999999999999 0 -0.043999999999999997 0 0 0</pose>
        <geometry>
          <sphere>
            <radius>0.029999999999999999</radius>
          </sphere>
        </geometry>
      </collision>
      <visual name="base_link_visual">
        <pose>0 0 0 0 0 0</pose>
        <geometry>
          <cylinder>
            <length>0.10000000000000001</length>
            <radius>0.20000000000000001</radius>
          </cylinder>
        </geometry>
        <material>
          <diffuse>0 0 1 1</diffuse>
          <ambient>0 0 1 1</ambient>
        </material>
      </visual>
      <visual name="base_link_fixed_joint_lump__front_caster_visual_1">
        <pose>0.14999999999999999 0 -0.043999999999999997 0 0 0</pose>
        <geometry>
          <sphere>
            <radius>0.029999999999999999</radius>
          </sphere>
        </geometry>
        <material>
          <diffuse>0.625 0.625 0.625 1</diffuse>
          <ambient>0.625 0.625 0.625 1</ambient>
        </material>
      </visual>
      <visual name="base_link_fixed_joint_lump__rear_caster_visual_2">
        <pose>-0.14999999999999999 0 -0.043999999999999997 0 0 0</pose>
        <geometry>
          <sphere>
            <radius>0.029999999999999999</radius>
          </sphere>
        </geometry>
        <material>
          <diffuse>0.625 0.625 0.625 1</diffuse>
          <ambient>0.625 0.625 0.625 1</ambient>
        </material>
      </visual>
    </link>
    <joint name="left_wheel_joint" type="revolute">
      <pose relative_to="base_link">0 -0.14999999999999999 -0.025000000000000001 1.5708 0 0</pose>
      <parent>base_link</parent>
      <child>left_wheel</child>
      <axis>
        <xyz>0 0 1</xyz>
        <limit>
          <lower>-inf</lower>
          <upper>inf</upper>
        </limit>
        <dynamics>
          <spring_reference>0</spring_reference>
          <spring_stiffness>0</spring_stiffness>
        </dynamics>
      </axis>
    </joint>
    <link name="left_wheel">
      <pose relative_to="left_wheel_joint">0 0 0 0 0 0</pose>
      <inertial>
        <pose>0 0 0 0 0 0</pose>
        <mass>0.5</mass>
        <inertia>
          <ixx>0.001</ixx>
          <ixy>0</ixy>
          <ixz>0</ixz>
          <iyy>0.001</iyy>
          <iyz>0</iyz>
          <izz>0.001</izz>
        </inertia>
      </inertial>
      <collision name="left_wheel_collision">
        <pose>0 0 0 0 0 0</pose>
        <geometry>
          <cylinder>
            <length>0.02</length>
            <radius>0.050000000000000003</radius>
          </cylinder>
        </geometry>
      </collision>
      <visual name="left_wheel_visual">
        <pose>0 0 0 0 0 0</pose>
        <geometry>
          <cylinder>
            <length>0.02</length>
            <radius>0.050000000000000003</radius>
          </cylinder>
        </geometry>
        <material>
          <diffuse>0 0 0 1</diffuse>
          <ambient>0 0 0 1</ambient>
        </material>
      </visual>
    </link>
    <joint name="right_wheel_joint" type="revolute">
      <pose relative_to="base_link">0 0.14999999999999999 -0.025000000000000001 1.5708 0 0</pose>
      <parent>base_link</parent>
      <child>right_wheel</child>
      <axis>
        <xyz>0 0 1</xyz>
        <limit>
          <lower>-inf</lower>
          <upper>inf</upper>
        </limit>
        <dynamics>
          <spring_reference>0</spring_reference>
          <spring_stiffness>0</spring_stiffness>
        </dynamics>
      </axis>
    </joint>
    <link name="right_wheel">
      <pose relative_to="right_wheel_joint">0 0 0 0 0 0</pose>
      <inertial>
        <pose>0 0 0 0 0 0</pose>
        <mass>0.5</mass>
        <inertia>
          <ixx>0.001</ixx>
          <ixy>0</ixy>
          <ixz>0</ixz>
          <iyy>0.001</iyy>
          <iyz>0</iyz>
          <izz>0.001</izz>
        </inertia>
      </inertial>
      <collision name="right_wheel_collision">
        <pose>0 0 0 0 0 0</pose>
        <geometry>
          <cylinder>
            <length>0.02</length>
            <radius>0.050000000000000003</radius>
          </cylinder>
        </geometry>
      </collision>
      <visual name="right_wheel_visual">
        <pose>0 0 0 0 0 0</pose>
        <geometry>
          <cylinder>
            <length>0.02</length>
            <radius>0.050000000000000003</radius>
          </cylinder>
        </geometry>
        <material>
          <diffuse>0 0 0 1</diffuse>
          <ambient>0 0 0 1</ambient>
        </material>
      </visual>
    </link>
    <frame name="front_caster_joint" attached_to="base_link">
      <pose>0.14999999999999999 0 -0.043999999999999997 0 0 0</pose>
    </frame>
    <frame name="front_caster" attached_to="front_caster_joint">
      <pose>0 0 0 0 0 0</pose>
    </frame>
    <frame name="rear_caster_joint" attached_to="base_link">
      <pose>-0.14999999999999999 0 -0.043999999999999997 0 0 0</pose>
    </frame>
    <frame name="rear_caster" attached_to="rear_caster_joint">
      <pose>0 0 0 0 0 0</pose>
    </frame>
    <plugin filename="gz-sim-diff-drive-system" name="gz::sim::systems::DiffDrive">
      <left_joint>left_wheel_joint</left_joint>
      <right_joint>right_wheel_joint</right_joint>
      <wheel_separation>0.3</wheel_separation>
      <wheel_radius>0.05</wheel_radius>
      <odom_publish_frequency>50</odom_publish_frequency>
      <max_linear_acceleration>1.0</max_linear_acceleration>
      <min_linear_acceleration>-1.0</min_linear_acceleration>
      <max_angular_acceleration>2.0</max_angular_acceleration>
      <min_angular_acceleration>-2.0</min_angular_acceleration>
      <max_linear_velocity>0.5</max_linear_velocity>
      <min_linear_velocity>-0.5</min_linear_velocity>
      <max_angular_velocity>1.0</max_angular_velocity>
      <min_angular_velocity>-1.0</min_angular_velocity>
      <topic>cmd_vel</topic>
    </plugin>
  </model>
</sdf>